Workbook

Sheet ALI
A1: Nome | B1: Itens de Dados Referenciais | C1: Registros Lógicos | D1: Complexidade | E1: Tamanho (FP) | F1: Imagem da Tela
A2: Conta do Cliente (Tela Cadastro do Cliente) | B2: E-mail; CPF; Senha (hash); Data de criação; | C2: Cliente | D2: Simples | E2: 7 | F2: (Imagem 1)
A3: Saque (Tela Solicitar Saque) | B3: Valor; Chave Pix; Status; Data da solicitação; Data de conclusão; | C3: Saque | D3: Simples | E3: 7 | F3: (Imagem 2) | J3: Imagem 1
J26: Imagem 2

Sheet AIE
A1: Nome | B1: Itens de Dados Referenciais | C1: Registros Lógicos | D1: Complexidade | E1: Tamanho (FP) | F1: Imagem da Tela
A2: Confirmação de Boleto (Tela Retorno do Pagamento Boleto) | B2: Identificador da transação externa; Status da confirmação; Data e hora da confirmação; | C2: Confirmação de boleto | D2: Simples | E2: 5 | F2: (Imagem 1)
A3: Diretório de Chaves Pix, DICT (Tela Solicitar Saque) | B3: Chave Pix; Tipo da chave; Nome do titular; CPF do titular (mascarado); Situação da chave; | C3: Chave Pix (DICT) | D3: Simples | E3: 5 | F3: (Imagem 2) | M3: Imagem 1
M25: Imagem 2

Sheet EE
A1: Nome | B1: Quantidade de arquivos referenciados | C1: Quantidade de itens de dados referenciados | D1: Complexidade | E1: Tamanho (FP) | F1: Imagem da Tela
A2: Incluir conta de cliente (Tela Cadastro do Cliente) | B2: ALI Cliente; ALI Cobrança; AIE Consulta de CPF; | C2: 4 (campos de entrada: e-mail, CPF, senha, confirmação da senha); 1 (mensagem de retorno ao usuário); | D2: Complexo | E2: 6 | F2: (Imagem 1)
A3: Alterar conta de cliente (Tela Minha Conta) | B3: ALI Cliente; | C3: 3 (campos de entrada: e-mail, senha atual, nova senha); 1 (mensagem de retorno ao usuário); | D3: Simples | E3: 3 | F3: (Imagem 2) | N3: Imagem 1
A4: Excluir conta de cliente (Tela Excluir Conta do Cliente) | B4: ALI Cliente; ALI Cobrança; | C4: 2 (campos de entrada: senha de confirmação, confirmação da exclusão); 1 (mensagem de retorno ao usuário); | D4: Simples | E4: 3 | F4: (Imagem 3)
A5: Solicitar saque via Pix (Tela Solicitar Saque) | B5: ALI Saque; ALI Business; ALI Movimentação; AIE DICT de chaves Pix; | C5: 2 (campos de entrada: valor, chave Pix); 1 (mensagem de retorno ao usuário); | D5: Moderado | E5: 4 | F5: (Imagem 4)
A6: Contribuição Para EE
A7: Fiquei responsável pelas Entradas Externas de Incluir conta de cliente, Alterar conta de cliente, Excluir conta de cliente e Solicitar saque via Pix. Identifiquei os ALIs e AIEs que cada transação usa, contei os itens de dados e defini a complexidade e o tamanho de cada uma.
N13: Imagem 2
N40: Imagem 3
N67: Imagem 4

Sheet SE
A1: Nome | B1: Quantidade de arquivos referenciados | C1: Quantidade de itens de dados referenciados | D1: Complexidade | E1: Tamanho (FP) | F1: Explicação | G1: Imagem da Tela
A2: Listar cobranças do cliente com totais (Tela Minhas Cobranças) | B2: ALI Cliente; ALI Cobrança; ALI Pagamento; ALI Business; | C2: 2 (filtros: CPF do cliente, filtro de status); 7 (colunas da listagem: nome do business, descrição, valor, status, data de criação, data do pagamento, método utilizado); 3 (totais calculados: total pago, total pendente, quantidade de cobranças); | D2: Complexo | E2: 7 | F2: O total pago, o total pendente e a quantidade de cobranças resultam de somas e contagens sobre as cobranças e os pagamentos do cliente. Esses números são derivados e não ficam gravados. | G2: (Imagem 1)
A3: Emitir comprovante de saque (Tela Comprovante de Saque) | B3: ALI Saque; ALI Business; | C3: 7 (dados do saque e do business: código, valor, chave Pix, status, data e hora da solicitação, data de conclusão, nome do business); 2 (saldos calculados: saldo anterior e saldo posterior); | D3: Moderado | E3: 5 | F3: Os saldos anterior e posterior ao saque são calculados a partir do saldo atual do business e do valor sacado, e o arquivo do comprovante é gerado pelo sistema. Ambos são dados derivados. | G3: (Imagem 2)
L4: Imagem 1
L31: Imagem 2

Sheet CE
A1: Nome | B1: Entrada Quantidade Arquivos Referenciados | C1: Entrada Quantidade de itens de dados referenciados | D1: Complexidade Entrada | E1: Tamanho Entrada (FP) | F1: Saída Quantidade Arquivos Referenciados | G1: Saída Quantidade de itens de dados referenciados | H1: Complexidade Saída | I1: Tamanho Saída (FP) | J1: Tamanho Final (FP) | K1: Imagem
A2: Validar chave Pix de destino (Tela Solicitar Saque) | B2: AIE DICT de chaves Pix; | C2: Chave Pix; | D2: Simples | E2: 3 | F2: AIE DICT de chaves Pix; | G2: Tipo da chave; Nome do titular; CPF do titular (mascarado); Situação da chave; | H2: Simples | I2: 3 | J2: 3 | K2: (Imagem 1) | P2: Imagem 1
A3: Listar saques recentes (Tela Solicitar Saque) | B3: ALI Saque; | C3: Página; | D3: Simples | E3: 3 | F3: ALI Saque; | G3: Valor do saque; Data da solicitação; Data de conclusão; Status do saque; | H3: Simples | I3: 3 | J3: 3 | K3: (Imagem 2)
P18: Imagem 2

Sheet Calculo
A1: Pontos de Função Brutos (PFB = ALI + AIE + EE + SE + CE)
A2: Tipo | B2: Função | C2: Complexidade | D2: Pontos de Função
A3: ALI | B3: =(ALI!A2) -> Conta do Cliente (Tela Cadastro do Cliente) | C3: =(ALI!D2) -> Simples | D3: =(ALI!E2) -> 7
A4: ALI | B4: =(ALI!A3) -> Saque (Tela Solicitar Saque) | C4: =(ALI!D3) -> Simples | D4: =(ALI!E3) -> 7
A5: Total ALI | D5: =(SUM(D3:D4)) -> 14
A6: AIE | B6: =(AIE!A2) -> Confirmação de Boleto (Tela Retorno do Pagamento Boleto) | C6: =(AIE!D2) -> Simples | D6: =(AIE!E2) -> 5
A7: AIE | B7: =(AIE!A3) -> Diretório de Chaves Pix, DICT (Tela Solicitar Saque) | C7: =(AIE!D3) -> Simples | D7: =(AIE!E3) -> 5
A8: Total AIE | D8: =(SUM(D6:D7)) -> 10
A9: EE | B9: =(EE!A2) -> Incluir conta de cliente (Tela Cadastro do Cliente) | C9: =(EE!D2) -> Complexo | D9: =(EE!E2) -> 6
A10: EE | B10: =(EE!A3) -> Alterar conta de cliente (Tela Minha Conta) | C10: =(EE!D3) -> Simples | D10: =(EE!E3) -> 3
A11: EE | B11: =(EE!A4) -> Excluir conta de cliente (Tela Excluir Conta do Cliente) | C11: =(EE!D4) -> Simples | D11: =(EE!E4) -> 3
A12: EE | B12: =(EE!A5) -> Solicitar saque via Pix (Tela Solicitar Saque) | C12: =(EE!D5) -> Moderado | D12: =(EE!E5) -> 4
A13: Total EE | D13: =(SUM(D9:D12)) -> 16
A14: SE | B14: =(SE!A2) -> Listar cobranças do cliente com totais (Tela Minhas Cobranças) | C14: =(SE!D2) -> Complexo | D14: =(SE!E2) -> 7
A15: SE | B15: =(SE!A3) -> Emitir comprovante de saque (Tela Comprovante de Saque) | C15: =(SE!D3) -> Moderado | D15: =(SE!E3) -> 5
A16: Total SE | D16: =(SUM(D14:D15)) -> 12
A17: CE | B17: =(CE!A2) -> Validar chave Pix de destino (Tela Solicitar Saque) | C17: =(CE!H2) -> Simples | D17: =(CE!J2) -> 3
A18: CE | B18: =(CE!A3) -> Listar saques recentes (Tela Solicitar Saque) | C18: =(CE!H3) -> Simples | D18: =(CE!J3) -> 3
A19: Total CE | D19: =(SUM(D17:D18)) -> 6
A20: PFB | B20: Pontos de Função Brutos | D20: =(D5+D8+D13+D16+D19) -> 58
A24: Características Gerais da Aplicação (CGA) – Nível de Influência (NI)
A25: Nº | B25: Característica | C25: Nível (0 a 5) | D25: Grau de influência | E25: Justificativa
A26: 1 | B26: Comunicação de dados | C26: 4 | D26: =CHOOSE(C26+1,"Nenhuma","Mínima","Moderada","Média","Significativa","Grande") -> Significativa | E26: O sistema só é acessado pelo navegador, pela internet, e conversa com vários serviços externos por API e webhooks: gateways de Pix, cartão, boleto e cripto, o DICT e a consulta de CPF. Há mais de um tipo de comunicação, mas todos sobre HTTPS.
A27: 2 | B27: Processamento distribuído | C27: 2 | D27: =CHOOSE(C27+1,"Nenhuma","Mínima","Moderada","Média","Significativa","Grande") -> Moderada | E27: A aplicação e o banco são centralizados em um único ambiente em nuvem. Só a validação de pagamentos e a consulta de chaves e CPF ocorrem em serviços de terceiros.
A28: 3 | B28: Desempenho | C28: 3 | D28: =CHOOSE(C28+1,"Nenhuma","Mínima","Moderada","Média","Significativa","Grande") -> Média | E28: O tempo de resposta importa no fluxo de pagamento, pois o cliente espera o QR Code e a confirmação, mas não há exigência contratual de tempo nem processamento crítico em tempo real.
A29: 4 | B29: Utilização de equipamento | C29: 2 | D29: =CHOOSE(C29+1,"Nenhuma","Mínima","Moderada","Média","Significativa","Grande") -> Moderada | E29: O MultiPag roda em recursos padrão de nuvem, sem restrição de hardware ou de operação que obrigue um cuidado especial com a configuração.
A30: 5 | B30: Volume de transações | C30: 3 | D30: =CHOOSE(C30+1,"Nenhuma","Mínima","Moderada","Média","Significativa","Grande") -> Média | E30: Vários businesses emitem cobranças e vários clientes pagam ao mesmo tempo, com picos no início do mês por causa das cobranças recorrentes, mas sem um pico crítico fixo.
A31: 6 | B31: Entrada on-line | C31: 5 | D31: =CHOOSE(C31+1,"Nenhuma","Mínima","Moderada","Média","Significativa","Grande") -> Grande | E31: Todas as entradas são feitas on-line, por formulários (cadastro, cobrança, pagamento, saque) e por retornos automáticos dos gateways. Não existe processamento em lote.
A32: 7 | B32: Eficiência do usuário final | C32: 4 | D32: =CHOOSE(C32+1,"Nenhuma","Mínima","Moderada","Média","Significativa","Grande") -> Significativa | E32: Os fluxos são guiados em etapas, com validação na hora (CPF verificado, chave Pix encontrada), botão de copiar código, QR Code e totais já calculados, para reduzir o esforço do usuário.
A33: 8 | B33: Atualização on-line | C33: 4 | D33: =CHOOSE(C33+1,"Nenhuma","Mínima","Moderada","Média","Significativa","Grande") -> Significativa | E33: Cobrança, pagamento, saldo, extrato e saque são atualizados on-line a cada operação, com recuperação pelo status. Não há duplicação de dados em tempo real nem recuperação automática completa, por isso a nota não é 5.
A34: 9 | B34: Complexidade do processamento | C34: 3 | D34: =CHOOSE(C34+1,"Nenhuma","Mínima","Moderada","Média","Significativa","Grande") -> Média | E34: Há regras de negócio moderadas: controle de status da cobrança, validação de saldo, cálculo de cotação e de totais, autenticação e senha com hash. Não há algoritmos matemáticos complexos.
A35: 10 | B35: Reutilização de código | C35: 2 | D35: =CHOOSE(C35+1,"Nenhuma","Mínima","Moderada","Média","Significativa","Grande") -> Moderada | E35: O reaproveitamento se limita ao modelo de dados e à especificação da API. O MultiPag não é uma solução white label, então grande parte do código será específica.
A36: 11 | B36: Facilidade de implantação | C36: 2 | D36: =CHOOSE(C36+1,"Nenhuma","Mínima","Moderada","Média","Significativa","Grande") -> Moderada | E36: A publicação em nuvem é simples, mas a implantação exige configurar as integrações com os gateways e cadastrar os businesses iniciais, sem requisito formal de conversão de dados.
A37: 12 | B37: Facilidade operacional | C37: 3 | D37: =CHOOSE(C37+1,"Nenhuma","Mínima","Moderada","Média","Significativa","Grande") -> Média | E37: A operação depende de rotinas de backup, registro de transações (RNF09) e acompanhamento da confirmação dos pagamentos, com algum procedimento manual quando um gateway falha.
... A39: 14 | B39: Facilidade de mudanças | C39: 2 | D39: =CHOOSE(C39+1,"Nenhuma","Mínima","Moderada","Média","Significativa","Grande") -> Moderada | E39: As regras ficam no código, e um novo método de pagamento ou novo tipo de cobrança exige alteração pontual. O usuário só configura filtros e os métodos habilitados de cada cobrança.
A40: NI | B40: Nível de Influência total (soma das 14 CGA) | C40: =SUM(C26:C39) -> 42
A43: Fator de Ajuste (FA) e Pontos de Função Ajustados (PFA)
A44: Indicador | B44: Descrição | C44: Valor
A45: FA | B45: Fator de Ajuste | C45: =(C40*0.01)+0.65 -> 1.07
A46: PFA | B46: Pontos de Função Ajustados | C46: =D20*C45 -> 62.06
...
